Workbook
Name B4b1000: Magazzino!$B$4

Sheet Magazzino
A3: Colonna 1 | B3: PRODOTTI | C3: GIACENZA AGGIORNATA | D3: GIACENZA INIZIALE | E3: PREZZO | F3: TOTALE AGGIORNATO
B4: ACCHIAPPA COLORE | C4: =SUMIF(Carico!$B$3:$B$975,B4,Carico!$C$3:$C$975)-(SUMIF(Scarico!$B$3:$B$997,B4,Scarico!$C$3:$C$997))+$D$4:$D$987 -> 18 | F4: =SUM(F6:F994) -> 2598.39
B5: ACQUA STIRO DISTILLATA 5LT | C5: =SUMIF(Carico!$B$3:$B$975,B5,Carico!$C$3:$C$975)-(SUMIF(Scarico!$B$3:$B$997,B5,Scarico!$C$3:$C$997))+$D$4:$D$987 -> 3 | E5: 1.29 | F5: =E5*C5 -> 3.87
B6: ALCOOL 1LT | C6: =SUMIF(Carico!$B$3:$B$975,B6,Carico!$C$3:$C$975)-(SUMIF(Scarico!$B$3:$B$997,B6,Scarico!$C$3:$C$997))+$D$4:$D$987 -> 5 | E6: 1.59 | F6: =E6*C6 -> 7.95
B7: AMUCHINA 1LT | C7: =SUMIF(Carico!$B$3:$B$975,B7,Carico!$C$3:$C$975)-(SUMIF(Scarico!$B$3:$B$997,B7,Scarico!$C$3:$C$997))+$D$4:$D$987 -> 4 | E7: 7.5 | F7: =E7*C7 -> 30
B8: AMULSIO STIRA BENE | C8: =SUMIF(Carico!$B$3:$B$975,B8,Carico!$C$3:$C$975)-(SUMIF(Scarico!$B$3:$B$997,B8,Scarico!$C$3:$C$997))+$D$4:$D$987 -> 0 | E8: 2.5 | F8: =E8*C8 -> 0
B9: ANTITARME ALIMENTARI (SCADUTO) | C9: =SUMIF(Carico!$B$3:$B$975,B9,Carico!$C$3:$C$975)-(SUMIF(Scarico!$B$3:$B$997,B9,Scarico!$C$3:$C$997))+$D$4:$D$987 -> 0 | F9: =E9*C9 -> 0
B10: ARGENTIL SPRAY | C10: =SUMIF(Carico!$B$3:$B$975,B10,Carico!$C$3:$C$975)-(SUMIF(Scarico!$B$3:$B$997,B10,Scarico!$C$3:$C$997))+$D$4:$D$987 -> 2 | E10: 17 | F10: =E10*C10 -> 34
B11: ARIA SANA UMIDITÁ | C11: =SUMIF(Carico!$B$3:$B$975,B11,Carico!$C$3:$C$975)-(SUMIF(Scarico!$B$3:$B$997,B11,Scarico!$C$3:$C$997))+$D$4:$D$987 -> 5 | F11: =E11*C11 -> 0
B12: ASCIUGATUTTO X CUCINA | C12: =SUMIF(Carico!$B$3:$B$975,B12,Carico!$C$3:$C$975)-(SUMIF(Scarico!$B$3:$B$997,B12,Scarico!$C$3:$C$997))+$D$4:$D$987 -> 0 | F12: =E12*C12 -> 0
B13: BACINELLE BUCATO | C13: =SUMIF(Carico!$B$3:$B$975,B13,Carico!$C$3:$C$975)-(SUMIF(Scarico!$B$3:$B$997,B13,Scarico!$C$3:$C$997))+$D$4:$D$987 -> 0 | F13: =E13*C13 -> 0
B14: BALSAMO FRUCTIS GARNIER ** | C14: =SUMIF(Carico!$B$3:$B$975,B14,Carico!$C$3:$C$975)-(SUMIF(Scarico!$B$3:$B$997,B14,Scarico!$C$3:$C$997))+$D$4:$D$987 -> 18 | E14: 3.5 | F14: =E14*C14 -> 63
B15: BIALCOL | C15: =SUMIF(Carico!$B$3:$B$975,B15,Carico!$C$3:$C$975)-(SUMIF(Scarico!$B$3:$B$997,B15,Scarico!$C$3:$C$997))+$D$4:$D$987 -> 0 | F15: =E15*C15 -> 0
B16: BICARBONATO ALIMENTARE 1KG | C16: =SUMIF(Carico!$B$3:$B$975,B16,Carico!$C$3:$C$975)-(SUMIF(Scarico!$B$3:$B$997,B16,Scarico!$C$3:$C$997))+$D$4:$D$987 -> 5 | E16: 2 | F16: 2.59
B17: BIOHY X TAPPETI shampoo | C17: =SUMIF(Carico!$B$3:$B$975,B17,Carico!$C$3:$C$975)-(SUMIF(Scarico!$B$3:$B$997,B17,Scarico!$C$3:$C$997))+$D$4:$D$987 -> 4 | E17: 30 | F17: =E17*C17 -> 120
B18: BLUHOME PROF. BUCATO FIORI ARANCIO | C18: =SUMIF(Carico!$B$3:$B$975,B18,Carico!$C$3:$C$975)-(SUMIF(Scarico!$B$3:$B$997,B18,Scarico!$C$3:$C$997))+$D$4:$D$987 -> 0 | F18: =E18*C18 -> 0
B19: BLUHOME PROF. BUCATO FIORI PULITO | C19: =SUMIF(Carico!$B$3:$B$975,B19,Carico!$C$3:$C$975)-(SUMIF(Scarico!$B$3:$B$997,B19,Scarico!$C$3:$C$997))+$D$4:$D$987 -> 0 | F19: =E19*C19 -> 0
B20: BOROTALCO BUSTE POLVERE | C20: =SUMIF(Carico!$B$3:$B$975,B20,Carico!$C$3:$C$975)-(SUMIF(Scarico!$B$3:$B$997,B20,Scarico!$C$3:$C$997))+$D$4:$D$987 -> 13 | F20: =E20*C20 -> 0
B21: BOROTALCO DOCCIA ORIGINAL ** | C21: =SUMIF(Carico!$B$3:$B$975,B21,Carico!$C$3:$C$975)-(SUMIF(Scarico!$B$3:$B$997,B21,Scarico!$C$3:$C$997))+$D$4:$D$987 -> 1 | E21: 2.88 | F21: =E21*C21 -> 2.88
B22: BOROTALCO INVISIBILE SPRAY | C22: =SUMIF(Carico!$B$3:$B$975,B22,Carico!$C$3:$C$975)-(SUMIF(Scarico!$B$3:$B$997,B22,Scarico!$C$3:$C$997))+$D$4:$D$987 -> 24 | E22: 5.9 | F22: =E22*C22 -> 141.6
B23: BRICOMEX - OLIO DI LINO 5 LT. | C23: =SUMIF(Carico!$B$3:$B$975,B23,Carico!$C$3:$C$975)-(SUMIF(Scarico!$B$3:$B$997,B23,Scarico!$C$3:$C$997))+$D$4:$D$987 -> 0 | F23: =E23*C23 -> 0
B24: BROX CANCELLA SU MURO - GOMMA | C24: =SUMIF(Carico!$B$3:$B$975,B24,Carico!$C$3:$C$975)-(SUMIF(Scarico!$B$3:$B$997,B24,Scarico!$C$3:$C$997))+$D$4:$D$987 -> 10 | F24: =E24*C24 -> 0
B25: CALGON 1.5 LT | C25: =SUMIF(Carico!$B$3:$B$975,B25,Carico!$C$3:$C$975)-(SUMIF(Scarico!$B$3:$B$997,B25,Scarico!$C$3:$C$997))+$D$4:$D$987 -> 0 | F25: =E25*C25 -> 0
B26: CALGON 2 LT. | C26: =SUMIF(Carico!$B$3:$B$975,B26,Carico!$C$3:$C$975)-(SUMIF(Scarico!$B$3:$B$997,B26,Scarico!$C$3:$C$997))+$D$4:$D$987 -> 2 | F26: =E26*C26 -> 0
B27: CALGON 750 CC | C27: =SUMIF(Carico!$B$3:$B$975,B27,Carico!$C$3:$C$975)-(SUMIF(Scarico!$B$3:$B$997,B27,Scarico!$C$3:$C$997))+$D$4:$D$987 -> 5 | F27: =E27*C27 -> 0
B28: CALGON PASTIGLIE ANTICALC. LAVATRICE | C28: =SUMIF(Carico!$B$3:$B$975,B28,Carico!$C$3:$C$975)-(SUMIF(Scarico!$B$3:$B$997,B28,Scarico!$C$3:$C$997))+$D$4:$D$987 -> 2 | F28: =E28*C28 -> 0
B29: CARRELLO BIDONE CARRY ECO | C29: =SUMIF(Carico!$B$3:$B$975,B29,Carico!$C$3:$C$975)-(SUMIF(Scarico!$B$3:$B$997,B29,Scarico!$C$3:$C$997))+$D$4:$D$987 -> 0 | F29: =E29*C29 -> 0
B30: CARTA FORNO | C30: =SUMIF(Carico!$B$3:$B$975,B30,Carico!$C$3:$C$975)-(SUMIF(Scarico!$B$3:$B$997,B30,Scarico!$C$3:$C$997))+$D$4:$D$987 -> 10 | F30: =E30*C30 -> 0
B31: CARTA IGIENICA X 4 | C31: =SUMIF(Carico!$B$3:$B$975,B31,Carico!$C$3:$C$975)-(SUMIF(Scarico!$B$3:$B$997,B31,Scarico!$C$3:$C$997))+$D$4:$D$987 -> 40 | E31: 2.39 | F31: =E31*C31 -> 95.6
B32: CEPPO COLTELLI + COLTELLI | C32: =SUMIF(Carico!$B$3:$B$975,B32,Carico!$C$3:$C$975)-(SUMIF(Scarico!$B$3:$B$997,B32,Scarico!$C$3:$C$997))+$D$4:$D$987 -> 0 | F32: =E32*C32 -> 0
B33: NAPISAN CURA LAVATRICE IGIENIZZANTE | C33: =SUMIF(Carico!$B$3:$B$975,B33,Carico!$C$3:$C$975)-(SUMIF(Scarico!$B$3:$B$997,B33,Scarico!$C$3:$C$997))+$D$4:$D$987 -> 7 | E33: 5.5 | F33: =E33*C33 -> 38.5
B34: CHANTECLAIR E RICARICHE | C34: =SUMIF(Carico!$B$3:$B$975,B34,Carico!$C$3:$C$975)-(SUMIF(Scarico!$B$3:$B$997,B34,Scarico!$C$3:$C$997))+$D$4:$D$987 -> 0 | E34: 2 | F34: =E34*C34 -> 0
B35: CHANTECLAYS SPRAY KIT | C35: =SUMIF(Carico!$B$3:$B$975,B35,Carico!$C$3:$C$975)-(SUMIF(Scarico!$B$3:$B$997,B35,Scarico!$C$3:$C$997))+$D$4:$D$987 -> 9 | E35: 2.5 | F35: =E35*C35 -> 22.5
B36: CIF CREMA CANDEGGINA | C36: =SUMIF(Carico!$B$3:$B$975,B36,Carico!$C$3:$C$975)-(SUMIF(Scarico!$B$3:$B$997,B36,Scarico!$C$3:$C$997))+$D$4:$D$987 -> 1 | F36: =E36*C36 -> 0
B37: CIF CREMA GREEN ACTIVE | C37: =SUMIF(Carico!$B$3:$B$975,B37,Carico!$C$3:$C$975)-(SUMIF(Scarico!$B$3:$B$997,B37,Scarico!$C$3:$C$997))+$D$4:$D$987 -> 8 | E37: 7.99 | F37: =E37*C37 -> 63.92
B38: CIF PIATTI 1 LT | C38: =SUMIF(Carico!$B$3:$B$975,B38,Carico!$C$3:$C$975)-(SUMIF(Scarico!$B$3:$B$997,B38,Scarico!$C$3:$C$997))+$D$4:$D$987 -> 0 | F38: =E38*C38 -> 0
B39: CIF PIATTI 2 LT | C39: =SUMIF(Carico!$B$3:$B$975,B39,Carico!$C$3:$C$975)-(SUMIF(Scarico!$B$3:$B$997,B39,Scarico!$C$3:$C$997))+$D$4:$D$987 -> 8 | E39: 2.99 | F39: =E39*C39 -> 23.92
B40: COCCOLINO AMMORBIDENTE 3 LT | C40: =SUMIF(Carico!$B$3:$B$975,B40,Carico!$C$3:$C$975)-(SUMIF(Scarico!$B$3:$B$997,B40,Scarico!$C$3:$C$997))+$D$4:$D$987 -> 9 | E40: 3.59 | F40: =E40*C40 -> 32.31
B41: FABULOSO AMMORBIDENTE 1,5 LT. | C41: =SUMIF(Carico!$B$3:$B$975,B41,Carico!$C$3:$C$975)-(SUMIF(Scarico!$B$3:$B$997,B41,Scarico!$C$3:$C$997))+$D$4:$D$987 -> 0 | E41: 3.69 | F41: =E41*C41 -> 0
B42: COPRI SCARPE | C42: =SUMIF(Carico!$B$3:$B$975,B42,Carico!$C$3:$C$975)-(SUMIF(Scarico!$B$3:$B$997,B42,Scarico!$C$3:$C$997))+$D$4:$D$987 -> 0 | F42: =E42*C42 -> 0
...

Sheet Scarico
A2: Colonna 1 | B2: PRODOTTI SCARICO | C2: PEZZI SCARICATI | D2: PRODOTTI IN GIACENZA | E2: DESTINAZIONE | F2: DATA
B3: VELINE RETTANGOLARI | C3: 2 | D3: =IF(B3="","",VLOOKUP(B3,Magazzino!$B$4:$D$987,2)) -> -2 | E3: CASA AU | F3: 46067
B4: VANISH OXI ACTION | C4: 1 | D4: =IF(B4="","",VLOOKUP(B4,Magazzino!$B$4:$D$987,2)) -> -2 | E4: CASA AU | F4: 46067
B5: MAURYS ASCIUGA ROTOLI X2 | C5: 1 | D5: =IF(B5="","",VLOOKUP(B5,Magazzino!$B$4:$D$987,2)) -> 17 | E5: CASA AU | F5: 46067
B6: TOVAGLIOLI RISPARMIO CASA 33X33 | C6: 2 | D6: =IF(B6="","",VLOOKUP(B6,Magazzino!$B$4:$D$987,2)) -> 102 | E6: CASA AU | F6: 46067
B7: SWIFFER KIT PAVIMENTO | C7: 1 | D7: =IF(B7="","",VLOOKUP(B7,Magazzino!$B$4:$D$987,2)) -> 18 | E7: CASA AU | F7: 46067
B8: ACQUA STIRO DISTILLATA 5LT | C8: 1 | D8: =IF(B8="","",VLOOKUP(B8,Magazzino!$B$4:$D$987,2)) -> 3 | E8: CASA AU | F8: 46067
B9: SACCHI NERI 70X110 (COND.) X10 | C9: 1 | D9: =IF(B9="","",VLOOKUP(B9,Magazzino!$B$4:$D$987,2)) -> 6 | E9: CASA AU | F9: 46067
B10: CARTA IGIENICA X 4 | C10: 2 | D10: =IF(B10="","",VLOOKUP(B10,Magazzino!$B$4:$D$987,2)) -> 40 | E10: AVV. | F10: 46065
B11: VELINE QUADRATE ** | C11: 4 | D11: =IF(B11="","",VLOOKUP(B11,Magazzino!$B$4:$D$987,2)) -> -2 | E11: AVV. | F11: 46065
B12: FISSAN SALVIETTE DELICATE | C12: 3 | D12: =IF(B12="","",VLOOKUP(B12,Magazzino!$B$4:$D$987,2)) -> 192 | E12: CASA AU | F12: 46066
B13: FAIRY CAPS LAVASTOVIGLIE GRANDI | C13: 2 | D13: =IF(B13="","",VLOOKUP(B13,Magazzino!$B$4:$D$987,2)) -> 0 | E13: AVV. | F13: 46066
B14: TOVAGLIOLI 38X38 ** | C14: 2 | D14: =IF(B14="","",VLOOKUP(B14,Magazzino!$B$4:$D$987,2)) -> 10 | E14: AVV. | F14: 46066
... B416: SACCHETTI UFFICIO TRASP. | C416: 1 | D416: =IF(B416="","",VLOOKUP(B416,Magazzino!$B$4:$D$987,2)) -> 40 | E416: VICTORIA CASA AU | F416: 46179
B417: ALCOOL 1LT | C417: 1 | E417: VICTORIA CASA AU | F417: 46179
B418: MAURYS ASCIUGA ROTOLI X1 | C418: 1 | D418: =IF(B418="","",VLOOKUP(B418,Magazzino!$B$4:$D$987,2)) -> -8 | E418: VICTORIA CASA AU | F418: 46179
B419: IKEA SPAZZOLE LEVA PELI BASTIS KIT | C419: 1 | D419: =IF(B419="","",VLOOKUP(B419,Magazzino!$B$4:$D$987,2)) -> 25 | E419: VICTORIA CASA AU | F419: 46179
B420: BOROTALCO INVISIBILE SPRAY | C420: 5 | D420: =IF(B420="","",VLOOKUP(B420,Magazzino!$B$4:$D$987,2)) -> 24 | E420: AVV. | F420: 46181
B421: FELCE AZZURRA MANI ANTIBATTERICO 300ML | C421: 4 | D421: =IF(B421="","",VLOOKUP(B421,Magazzino!$B$4:$D$987,2)) -> 75 | E421: AVV. | F421: 46181
B422: SENSODYNE COMPLEX DAILY | C422: 4 | D422: =IF(B422="","",VLOOKUP(B422,Magazzino!$B$4:$D$987,2)) -> 12 | E422: AVV. | F422: 46181
B423: ACQUA STIRO DISTILLATA 5LT | C423: 2 | D423: =IF(B423="","",VLOOKUP(B423,Magazzino!$B$4:$D$987,2)) -> 3 | E423: VICTORIA CASA AU | F423: 46181
B424: SACCHI NERI CONDOMINIO 80X120 (OPERAI-AVV.-GIARD.) | C424: 2 | D424: =IF(B424="","",VLOOKUP(B424,Magazzino!$B$4:$D$987,2)) -> 42 | E424: AVV. | F424: 46182
B425: CARTA IGIENICA X 4 | C425: 2 | D425: =IF(B425="","",VLOOKUP(B425,Magazzino!$B$4:$D$987,2)) -> 40 | E425: AVV. | F425: 46182
B426: OMINO BIANCO ADDITIVO | C426: 2 | D426: =IF(B426="","",VLOOKUP(B426,Magazzino!$B$4:$D$987,2)) -> 0 | E426: MARIANA CASA AU | F426: 46183
B427: CARTA IGIENICA X 4 | C427: 1 | D427: =IF(B427="","",VLOOKUP(B427,Magazzino!$B$4:$D$987,2)) -> 40 | E427: FERRANTE AMM. | F427: 46182
B428: DECAL C - DISINCROSTANTE 1 LT. | C428: 1 | D428: =IF(B428="","",VLOOKUP(B428,Magazzino!$B$4:$D$987,2)) -> -2 | E428: RICCI F. FREGENE | F428: 46183
B429: SACCHI NERI CONDOMINIO 80X120 (OPERAI-AVV.-GIARD.) | C429: 1 | D429: =IF(B429="","",VLOOKUP(B429,Magazzino!$B$4:$D$987,2)) -> 42 | E429: TARDIVI GIARD. | F429: 46184
... B457: CARTA IGIENICA X 4 | C457: 2 | D457: =IF(B457="","",VLOOKUP(B457,Magazzino!$B$4:$D$987,2)) -> 40 | E457: AVV. | F457: 46191
A458: F | B458: VILEDA PANNO MICROFIBRA XL | C458: 4 | D458: =IF(B458="","",VLOOKUP(B458,Magazzino!$B$4:$D$987,2)) -> -2 | E458: AVV. | F458: 46192
A459: F | B459: LYSOFORM DETERGENTE PAVIMENTI 1,1 LT | C459: 4 | D459: =IF(B459="","",VLOOKUP(B459,Magazzino!$B$4:$D$987,2)) -> 0 | E459: AVV. | F459: 46192
A460: F | B460: ALCOOL 1LT | C460: 4 | D460: =IF(B460="","",VLOOKUP(B460,Magazzino!$B$4:$D$987,2)) -> 5 | E460: AVV. | F460: 46192
A461: F | B461: WC NET CANDEGGINA GEL ** | C461: 4 | D461: =IF(B461="","",VLOOKUP(B461,Magazzino!$B$4:$D$987,2)) -> -2 | E461: AVV. | F461: 46192
A462: F | B462: VIAKAL SPRAY | C462: 4 | D462: =IF(B462="","",VLOOKUP(B462,Magazzino!$B$4:$D$987,2)) -> -2 | E462: AVV. | F462: 46192
A463: F | B463: MAURYS ASCIUGA ROTOLI X2 | C463: 1 | D463: =IF(B463="","",VLOOKUP(B463,Magazzino!$B$4:$D$987,2)) -> 17 | E463: AVV. | F463: 46192
A464: F | B464: TOVAGLIOLI 40X40 RISPARMIO CASA ** | C464: 4 | D464: =IF(B464="","",VLOOKUP(B464,Magazzino!$B$4:$D$987,2)) -> 10 | E464: AVV. | F464: 46192
A465: F | B465: CARTA IGIENICA X 4 | C465: 4 | D465: =IF(B465="","",VLOOKUP(B465,Magazzino!$B$4:$D$987,2)) -> 40 | E465: AVV. | F465: 46192
A466: F | B466: DIXAN CLASSICO 2 LT | C466: 3 | D466: =IF(B466="","",VLOOKUP(B466,Magazzino!$B$4:$D$987,2)) -> 0 | E466: AVV. | F466: 46192
A467: F | B467: COCCOLINO AMMORBIDENTE 3 LT | C467: 3 | D467: =IF(B467="","",VLOOKUP(B467,Magazzino!$B$4:$D$987,2)) -> 9 | E467: AVV. | F467: 46192
A468: F | B468: NAPISAN ADDITIVO LAVATRICE 2,2 LT. | C468: 3 | D468: =IF(B468="","",VLOOKUP(B468,Magazzino!$B$4:$D$987,2)) -> 5 | E468: AVV. | F468: 46192
A469: F | B469: ACCHIAPPA COLORE | C469: 2 | D469: =IF(B469="","",VLOOKUP(B469,Magazzino!$B$4:$D$987,2)) -> 18 | E469: AVV. | F469: 46192
...

Sheet Carico
A2: Colonna 1 | B2: PRODOTTI - CARICO MERCI | C2: QUANTITÁ | D2: FORNITORE | E2: DATA
B3: TOVAGLIOLI 40X40 RISPARMIO CASA ** | C3: 36 | D3: RISPARMIO CASA | E3: 46065
B4: TOVAGLIOLI 38X38 ** | C4: 3 | D4: GIACENZA | E4: 46065
B5: FELCE AZZURRA MANI ANTIBATTERICO 300ML | C5: 34 | D5: RISPARMIO CASA | E5: 46065
B6: ALCOOL 1LT | C6: 23 | D6: RISPARMIO CASA | E6: 46065
B7: FAIRY ORIGINAL 90 CAPS | C7: 8 | D7: RISPARMIO CASA | E7: 46065
B8: FAIRY LAVASTOVIGLIE PLATINUM 28 | C8: 3 | D8: GIACENZA | E8: 46065
B9: CARTA IGIENICA X 4 | C9: 31 | D9: RISPARMIO CASA | E9: 46065
B10: SWIFFER KIT SPOLVERO | C10: 4 | D10: GIACENZA | E10: 46065
B11: SWIFFER POLVERE RICARICHE | C11: 10 | D11: RISPARMIO CASA | E11: 46065
B12: SENSODYNE COMPLEX DAILY | C12: 9 | D12: RISPARMIO CASA | E12: 46065
B13: BOROTALCO DOCCIA ORIGINAL ** | C13: 4 | D13: RISPARMIO CASA | E13: 46065
B14: EMULSIO RAVVIVA PARQUET ** | C14: 11 | D14: RISPARMIO CASA | E14: 46065
... B346: COCCOLINO AMMORBIDENTE 3 LT | C346: 5 | D346: AMAZON | E346: 46301
